test_0 (__main__.lab2a.test_0)
[Lab 2] - [Investigation 1] - [Part 1] - variables & printing - Test for file creation: ./lab2a.py ... ok
test_1 (__main__.lab2a.test_1)
[Lab 2] - [Investigation 1] - [Part 1] - variables & printing - Test for errors running: ./lab2a.py ... /usr/lib64/python3.12/subprocess.py:822: ResourceWarning: unclosed file <_io.TextIOWrapper name=3 encoding='UTF-8'>
  _cleanup()
ResourceWarning: Enable tracemalloc to get the object allocation traceback
ok
test_2 (__main__.lab2a.test_2)
[Lab 2] - [Investigation 1] - [Part 1] - variables & printing - Test for correct shebang line: ./lab2a.py ... ok
test_3 (__main__.lab2a.test_3)
[Lab 2] - [Investigation 1] - [Part 1] - variables & printing - Test for correct output: ./lab2a.py ... ok
test_0 (__main__.lab2b.test_0)
[Lab 2] - [Investigation 1] - [Part 1] - using input() function - Test for file creation: ./lab2b.py ... ok
test_1 (__main__.lab2b.test_1)
[Lab 2] - [Investigation 1] - [Part 1] - using input() - Test for errors with sending input "Jon" "20": ./lab2b.py ... ok
test_2 (__main__.lab2b.test_2)
[Lab 2] - [Investigation 1] - [Part 1] - using input() - Test for correct shebang line: ./lab2b.py ... ok
test_3 (__main__.lab2b.test_3)
[Lab 2] - [Investigation 1] - [Part 1] - using input() - Test output with sending input "Jon" "20": ./lab2b.py ... ok
test_4 (__main__.lab2b.test_4)
[Lab 2] - [Investigation 1] - [Part 1] - using input() - Test output with sending input "Jen" "25": ./lab2b.py ... ok
test_0 (__main__.lab2c.test_0)
[Lab 2] - [Investigation 1] - [Part 2] - command line arguments - Test for file creation: ./lab2c.py ... FAIL

======================================================================
FAIL: test_0 (__main__.lab2c.test_0)
[Lab 2] - [Investigation 1] - [Part 2] - command line arguments - Test for file creation: ./lab2c.py
----------------------------------------------------------------------
Traceback (most recent call last):
  File "/home/sarjina/ops445/lab2/./CheckLab2.py", line 129, in test_0
    self.assertTrue(os.path.exists('./lab2c.py'), msg=error_output)
AssertionError: False is not true : your file cannot be found (HINT: make sure your file are in the correct directory)

----------------------------------------------------------------------
Ran 10 tests in 0.054s

FAILED (failures=1)
OPS445 Lab Report - System Information for running ./CheckLab2.py
=================================================================
    User login name: sarjina
    Git Email: skarki28@myseneca.ca
    Linux system name: fedora
    Python executable: /usr/bin/python3
    Python version:  3.12.4 (main, Jun  7 2024, 00:00:00) [GCC 14.1.1 20240607 (Red Hat 14.1.1-5)]
    OS Platform: linux
    Working Directory: /home/sarjina/ops445/lab2
    Start at: Fri Sep 27 19:41:21 2024
=================================================================
